Workbook

Sheet Transactions
A1: Date | B1: Category | C1: Description | D1: Type (Income/Expense) | E1: Amount | F1: Month
A2: 45880 | B2: Rent | C2: Security Deposit | D2: Expense | E2: 774 | F2: =TEXT(A2,"MMMM") -> August
A3: 45881 | B3: Electronics | C3: Mint | D3: Expense | E3: 209.68 | F3: =TEXT(A3,"MMMM") -> August
A4: 45883 | B4: Groceries | C4: Lidl | D4: Expense | E4: 25 | F4: =TEXT(A4,"MMMM") -> August
A5: 45885 | B5: Groceries | C5: Patel Brothers | D5: Expense | E5: 22.91 | F5: =TEXT(A5,"MMMM") -> August
A6: 45885 | B6: Electronics | C6: Wifi | D6: Expense | E6: 6.25 | F6: =TEXT(A6,"MMMM") -> August
A7: 45885 | B7: Transport | C7: Uber | D7: Expense | E7: 14.33 | F7: =TEXT(A7,"MMMM") -> August
A8: 45886 | B8: Groceries | C8: Walmart | D8: Expense | E8: 41.69 | F8: =TEXT(A8,"MMMM") -> August
A9: 45886 | B9: Groceries | C9: Walmart | D9: Expense | E9: 24.77 | F9: =TEXT(A9,"MMMM") -> August
A10: 45887 | B10: Groceries | C10: Lidl | D10: Expense | E10: 3.25 | F10: =TEXT(A10,"MMMM") -> August
A11: 45887 | B11: Groceries | C11: Lidl | D11: Expense | E11: 5.39 | F11: =TEXT(A11,"MMMM") -> August
A12: 45888 | B12: Cleaning | C12: Amazon | D12: Expense | E12: 15.5 | F12: =TEXT(A12,"MMMM") -> August
A13: 45890 | B13: Groceries | C13: Costco | D13: Expense | E13: 21.77 | F13: =TEXT(A13,"MMMM") -> August
... A29: 45905 | B29: Groceries | C29: Lidl Supplies | D29: Expense | E29: 2.5 | F29: =TEXT(A29,"MMMM") -> September
A30: 45906 | B30: Groceries | C30: Patel Bros | D30: Expense | E30: =12.43 -> 12.43 | F30: =TEXT(A30,"MMMM") -> September
A31: 45910 | B31: Groceries | C31: Lidl Supplies | D31: Expense | E31: =1.33+1.04 -> 2.37 | F31: =TEXT(A31,"MMMM") -> September
A32: 45913 | B32: Groceries | C32: Costco Supplies | D32: Expense | E32: 9.69 | F32: =TEXT(A32,"MMMM") -> September
A33: 45913 | B33: Electronics | C33: Walmart | D33: Expense | E33: 8.03 | F33: =TEXT(A33,"MMMM") -> September
A34: 45913 | B34: Food | C34: Pizza at Home | D34: Expense | E34: 2.93 | F34: =TEXT(A34,"MMMM") -> September
A35: 45916 | B35: Transport | C35: Anna Trip | D35: Expense | E35: 5 | F35: =TEXT(A35,"MMMM") -> September
A36: 45919 | B36: Transport | C36: Yber/Lyft | D36: Expense | E36: 12 | F36: =TEXT(A36,"MMMM") -> September
A37: 45919 | B37: Food | C37: Garba | D37: Expense | E37: 12 | F37: =TEXT(A37,"MMMM") -> September
A38: 45927 | B38: Transport | C38: Movie+ Popcorn | D38: Expense | E38: =11.4+4 -> 15.4 | F38: =TEXT(A38,"MMMM") -> September
A39: 45926 | B39: Groceries | C39: Lidl Tomatoes | D39: Expense | E39: 0.82 | F39: =TEXT(A39,"MMMM") -> September
A40: 45915 | B40: Grocereies | C40: Lidl Supplies | D40: Expense | E40: 2.89 | F40: =TEXT(A40,"MMMM") -> September
A41: 45916 | B41: Rent | C41: Renters Insurance | D41: Expense | E41: 3.12 | F41: =TEXT(A41,"MMMM") -> September
A42: 45918 | B42: Food | C42: Doordash Pass | D42: Expense | E42: 2.5 | F42: =TEXT(A42,"MMMM") -> September
A43: 45920 | B43: Groceries | C43: Lidl Supplies | D43: Expense | E43: =6.2+3.86 -> 10.06 | F43: =TEXT(A43,"MMMM") -> September
A44: 45925 | B44: Groceries | C44: Costco Supplies | D44: Expense | E44: 6.92 | F44: =TEXT(A44,"MMMM") -> September
A45: 45929 | B45: Groceries | C45: Patels | D45: Expense | E45: 19.41 | F45: =TEXT(A45,"MMMM") -> September
A46: 45929 | B46: Groceries | C46: Wee | D46: Expense | E46: 8.31 | F46: =TEXT(A46,"MMMM") -> September
A47: 45929 | B47: Rent | C47: Rent for September | D47: Expense | E47: 779.5 | F47: =TEXT(A47,"MMMM") -> September
A49: 45931 | B49: Food | C49: Anna Food | D49: Expense | E49: 16.95 | F49: =TEXT(A49,"MMMM") -> October
A50: 45931 | B50: Food | C50: Asia Cup Pizza | D50: Expense | E50: 3.53 | F50: =TEXT(A50,"MMMM") -> October
A51: 45931 | B51: Groceries | C51: Costco | D51: Expense | E51: 8.47 | F51: =TEXT(A51,"MMMM") -> October
A52: 45932 | B52: Groceries | C52: Lidl | D52: Expense | E52: 9.95 | F52: =TEXT(A52,"MMMM") -> October
A53: 45933 | B53: Electronics | C53: TV | D53: Expenses | E53: 26 | F53: =TEXT(A53,"MMMM") -> October
A54: 45933 | B54: Rent | C54: Security Deposit | D54: Expense | E54: 494.25 | F54: =TEXT(A54,"MMMM") -> October
A55: 45933 | B55: Wifi | C55: Monthly Xfinity | D55: Expense | E55: 12.73 | F55: =TEXT(A55,"MMMM") -> October
A56: 45934 | B56: Clothing | C56: Burlington | D56: Expense | E56: 75.33 | F56: =TEXT(A56,"MMMM") -> October
...

Sheet Dashboard
A1: Selected Month | B1: February
A3: Category | B3: Amount
A4: Groceries | B4: =SUMIFS(Transactions!E:E, Transactions!B:B, A4, Transactions!F:F, $B$1) -> 123.808
A5: Rent | B5: =SUMIFS(Transactions!E:E, Transactions!B:B, A5, Transactions!F:F, $B$1) -> 773.03
A6: Transport | B6: =SUMIFS(Transactions!E:E, Transactions!B:B, A6, Transactions!F:F, $B$1) -> 0
A7: Furniture | B7: =SUMIFS(Transactions!E:E, Transactions!B:B, A7, Transactions!F:F, $B$1) -> 0
A8: Cleaning | B8: =SUMIFS(Transactions!E:E, Transactions!B:B, A8, Transactions!F:F, $B$1) -> 0
A9: Electronics | B9: =SUMIFS(Transactions!E:E, Transactions!B:B, A9, Transactions!F:F, $B$1) -> 50.37
A10: Food | B10: =SUMIFS(Transactions!E:E, Transactions!B:B, A10, Transactions!F:F, $B$1) -> 13.24
A11: Clothing | B11: =SUMIFS(Transactions!E:E, Transactions!B:B, A11, Transactions!F:F, $B$1) -> 0
A12: Fun | B12: =SUMIFS(Transactions!E:E, Transactions!B:B, A12, Transactions!F:F, $B$1) -> 97.83
A15: Total Expense | B15: =SUM(B2:B12) -> 1058.278
